/blue/adamginsburg/abulatek/brick/scripts/bash
c0712a-s9.ufhpc
Wed Jul 27 14:36:01 EDT 2022
data_55
93
27
2
casa_clean_ab_93_spw27_2sigma_reimaging_FOV.log
--> CrashReporter initialized.

0%....10....20....30....40....50....60....70....80....90....100%
2022-07-27 18:39:49	WARN	SIImageStore::getPSFGaussian (file casa-source/code/synthesis/ImagerObjects/SIImageStore.cc, line 1916)	PSF is blank for[C1919:P0] 

0%....10....20....30....40....50....60....70....80....90....100%
2022-07-27 18:43:54	WARN	task_tclean::SIImageStore::restore (file casa-source/code/synthesis/ImagerObjects/SIImageStore.cc, line 2089)	Restoring with an empty model image. Only residuals will be processed to form the output restored image.
optional configuration file config.py not found, continuing CASA startup without it
[22;0t]0;IPython: scripts/bashUsing matplotlib backend: agg
Creating a new telemetry file
CASA 6.1.0.118 -- Common Astronomy Software Applications [6.1.0.118]
Data path is: /blue/adamginsburg/abulatek/brick/symlinks/data_55/calibrated_final.ms
Now creating dirty map: /blue/adamginsburg/abulatek/brick/symlinks/imaging_results/source_ab_93_spw27_reimaging_dirty
Dirty map creation successful!
Now measuring the mad_std in the dirty map
Standard deviation calculation successful! Result: 0.9 mJy/beam
Now masking the cube at 3 sigma
Masking successful!
Now computing boolmask
Boolmask computation successful!
Now getting coordinates from original image
Coordinates retrieved successfully!
Now outputting the mask file
Mask file output successful!
Now calculating the eroded/dilated boolmask
Eroded/dilated boolmask calculation successful!
Now defining the eroded/dilated mask to export
Now outputting the eroded/dilated mask
Eroded/dilated mask output successful!
Now renaming mask file for consistency
Telemetry initialized. Telemetry will send anonymized usage statistics to NRAO.
You can disable telemetry by adding the following line to the config.py file in your rcdir (e.g. ~/.casa/config.py):
telemetry_enabled = False
/blue/adamginsburg/adamginsburg/casa/casa-6.1.0-118/lib/py/lib/python3.6/site-packages/casa_formats_io/casa_dask.py:232: RuntimeWarning: divide by zero encountered in long_scalars
  factors = [f for f in range(stacks[dim] + 1) if stacks[dim] % f == 0]
WARNING: StokesWarning: Cube is a Stokes cube, returning spectral cube for I component [spectral_cube.io.core]
Traceback (most recent call last):
  File "/blue/adamginsburg/adamginsburg/casa/casa-6.1.0-118/lib/py/lib/python3.6/site-packages/casashell/private/init_system.py", line 159, in __evprop__
    run_path( args[0], init_globals=exec_globals, run_name='__main__' )
  File "/blue/adamginsburg/adamginsburg/casa/casa-6.1.0-118/lib/py/lib/python3.6/runpy.py", line 263, in run_path
    pkg_name=pkg_name, script_name=fname)
  File "/blue/adamginsburg/adamginsburg/casa/casa-6.1.0-118/lib/py/lib/python3.6/runpy.py", line 96, in _run_module_code
    mod_name, mod_spec, pkg_name, script_name)
  File "/blue/adamginsburg/adamginsburg/casa/casa-6.1.0-118/lib/py/lib/python3.6/runpy.py", line 85, in _run_code
    exec(code, run_globals)
  File "/blue/adamginsburg/abulatek/brick/scripts/imaging/reimaging_FOV.py", line 97, in <module>
    mask_image = make_mask(dirty_cube, dirty_map_image, sigma, 2, 2)
  File "/blue/adamginsburg/abulatek/brick/scripts/imaging/reimaging_FOV.py", line 80, in make_mask
    os.rename(mask_image+'.mask',mask_e_d_image+'.mask')
OSError: [Errno 39] Directory not empty: '/blue/adamginsburg/abulatek/brick/symlinks/imaging_results/source_ab_93_spw27_reimaging_dirty_3sigma.mask' -> '/blue/adamginsburg/abulatek/brick/symlinks/imaging_results/source_ab_93_spw27_reimaging_dirty_3sigma_e2_d2.mask'
data_5d
110
29
2
casa_clean_ab_110_spw29_2sigma_reimaging_FOV.log
--> CrashReporter initialized.

0%....10....20....30....40....50....60....70....80....90....100%
2022-07-27 18:48:38	WARN	SIImageStore::getPSFGaussian (file casa-source/code/synthesis/ImagerObjects/SIImageStore.cc, line 1916)	PSF is blank for[C0:P0] 

0%....10....20....30....40....50....60....70....80....90....100%
2022-07-27 18:52:42	WARN	task_tclean::SIImageStore::restore (file casa-source/code/synthesis/ImagerObjects/SIImageStore.cc, line 2089)	Restoring with an empty model image. Only residuals will be processed to form the output restored image.

0%....10....20....30....40....50....60....70....80....90....100%
2022-07-27 18:56:27	WARN	task_tclean::SIImageStore::getPSFGaussian (file casa-source/code/synthesis/ImagerObjects/SIImageStore.cc, line 1916)	PSF is blank for[C0:P0] 

0%....10....20....30....40....50....60....70....80....90....100%
2022-07-27 19:00:39	WARN	task_tclean::SIImageStore::getPSFGaussian (file casa-source/code/synthesis/ImagerObjects/SIImageStore.cc, line 1916)	PSF is blank for[C0:P0] 
2022-07-27 19:02:49	WARN	task_tclean::SIImageStore::getPSFGaussian (file casa-source/code/synthesis/ImagerObjects/SIImageStore.cc, line 1916)	PSF is blank for[C0:P0] 

0%....10....20....30....40....50....60....70....80....90....100%
2022-07-27 19:10:28	WARN	task_tclean::SIImageStore::getPSFGaussian (file casa-source/code/synthesis/ImagerObjects/SIImageStore.cc, line 1916)	PSF is blank for[C0:P0] 

0%....10....20....30....40....50....60....70....80....90....100%
2022-07-27 19:18:13	WARN	task_tclean::SIImageStore::getPSFGaussian (file casa-source/code/synthesis/ImagerObjects/SIImageStore.cc, line 1916)	PSF is blank for[C0:P0] 
optional configuration file config.py not found, continuing CASA startup without it
[22;0t]0;IPython: scripts/bashUsing matplotlib backend: agg
CASA 6.1.0.118 -- Common Astronomy Software Applications [6.1.0.118]
Data path is: /blue/adamginsburg/abulatek/brick/symlinks/data_5d/calibrated_final.ms
Now creating dirty map: /blue/adamginsburg/abulatek/brick/symlinks/imaging_results/source_ab_110_spw29_reimaging_dirty
Dirty map creation successful!
Now measuring the mad_std in the dirty map
Standard deviation calculation successful! Result: 0.9 mJy/beam
Now masking the cube at 3 sigma
Masking successful!
Now computing boolmask
Boolmask computation successful!
Now getting coordinates from original image
Coordinates retrieved successfully!
Now outputting the mask file
Mask file output successful!
Now calculating the eroded/dilated boolmask
Eroded/dilated boolmask calculation successful!
Now defining the eroded/dilated mask to export
Now outputting the eroded/dilated mask
Eroded/dilated mask output successful!
Now renaming mask file for consistency
Eroded/dilated mask file successfully renamed!
Now beginning deep clean: /blue/adamginsburg/abulatek/brick/symlinks/imaging_results/source_ab_110_spw29_reimaging_clean_2sigma_n50000_masked_3sigma_pbmask0p18
Deep clean complete!
Telemetry initialized. Telemetry will send anonymized usage statistics to NRAO.
You can disable telemetry by adding the following line to the config.py file in your rcdir (e.g. ~/.casa/config.py):
telemetry_enabled = False
/blue/adamginsburg/adamginsburg/casa/casa-6.1.0-118/lib/py/lib/python3.6/site-packages/casa_formats_io/casa_dask.py:232: RuntimeWarning: divide by zero encountered in long_scalars
  factors = [f for f in range(stacks[dim] + 1) if stacks[dim] % f == 0]
WARNING: StokesWarning: Cube is a Stokes cube, returning spectral cube for I component [spectral_cube.io.core]
data_31
146
51
2
casa_clean_ab_146_spw51_2sigma_reimaging_FOV.log
--> CrashReporter initialized.

0%....10....20....30....40....50....60....70....80....90....100%

0%....10....20....30....40....50....60....70....80....90....100%

0%....10....20....30....40....50....60....70....80....90....100%

0%....10....20....30....40....50....60....70....80....90....100%
2022-07-27 19:31:31	WARN	task_tclean::SIImageStore::restore (file casa-source/code/synthesis/ImagerObjects/SIImageStore.cc, line 2089)	Restoring with an empty model image. Only residuals will be processed to form the output restored image.
2022-07-27 19:33:27	SEVERE	tclean::task_tclean::casa	Exception from task_tclean : Restoration Error  : Error in copying internal T/F mask : Invalid Table operation: SetupNewTable /blue/adamginsburg/abulatek/brick/symlinks/imaging_results/source_ab_146_spw51_reimaging_dirty.image/mask0 is already opened (is in the table cache)
2022-07-27 19:33:28	SEVERE	tclean::::casa	Exception Reported: Error in tclean: Exception from task_tclean : Restoration Error  : Error in copying internal T/F mask : Invalid Table operation: SetupNewTable /blue/adamginsburg/abulatek/brick/symlinks/imaging_results/source_ab_146_spw51_reimaging_dirty.image/mask0 is already opened (is in the table cache)
optional configuration file config.py not found, continuing CASA startup without it
[22;0t]0;IPython: scripts/bashUsing matplotlib backend: agg
CASA 6.1.0.118 -- Common Astronomy Software Applications [6.1.0.118]
Data path is: /blue/adamginsburg/abulatek/brick/symlinks/data_31/calibrated_final.ms
Now creating dirty map: /blue/adamginsburg/abulatek/brick/symlinks/imaging_results/source_ab_146_spw51_reimaging_dirty
Dirty map creation successful!
Now measuring the mad_std in the dirty map
Standard deviation calculation successful! Result: 2.2 mJy/beam
Now masking the cube at 3 sigma
Masking successful!
Now computing boolmask
Boolmask computation successful!
Now getting coordinates from original image
Coordinates retrieved successfully!
Now outputting the mask file
Mask file output successful!
Now calculating the eroded/dilated boolmask
Eroded/dilated boolmask calculation successful!
Now defining the eroded/dilated mask to export
Now outputting the eroded/dilated mask
Eroded/dilated mask output successful!
Now renaming mask file for consistency
Telemetry initialized. Telemetry will send anonymized usage statistics to NRAO.
You can disable telemetry by adding the following line to the config.py file in your rcdir (e.g. ~/.casa/config.py):
telemetry_enabled = False
/blue/adamginsburg/adamginsburg/casa/casa-6.1.0-118/lib/py/lib/python3.6/site-packages/casa_formats_io/casa_dask.py:232: RuntimeWarning: divide by zero encountered in long_scalars
  factors = [f for f in range(stacks[dim] + 1) if stacks[dim] % f == 0]
WARNING: StokesWarning: Cube is a Stokes cube, returning spectral cube for I component [spectral_cube.io.core]
Traceback (most recent call last):
  File "/blue/adamginsburg/adamginsburg/casa/casa-6.1.0-118/lib/py/lib/python3.6/site-packages/casashell/private/init_system.py", line 159, in __evprop__
    run_path( args[0], init_globals=exec_globals, run_name='__main__' )
  File "/blue/adamginsburg/adamginsburg/casa/casa-6.1.0-118/lib/py/lib/python3.6/runpy.py", line 263, in run_path
    pkg_name=pkg_name, script_name=fname)
  File "/blue/adamginsburg/adamginsburg/casa/casa-6.1.0-118/lib/py/lib/python3.6/runpy.py", line 96, in _run_module_code
    mod_name, mod_spec, pkg_name, script_name)
  File "/blue/adamginsburg/adamginsburg/casa/casa-6.1.0-118/lib/py/lib/python3.6/runpy.py", line 85, in _run_code
    exec(code, run_globals)
  File "/blue/adamginsburg/abulatek/brick/scripts/imaging/reimaging_FOV.py", line 97, in <module>
    mask_image = make_mask(dirty_cube, dirty_map_image, sigma, 2, 2)
  File "/blue/adamginsburg/abulatek/brick/scripts/imaging/reimaging_FOV.py", line 80, in make_mask
    os.rename(mask_image+'.mask',mask_e_d_image+'.mask')
OSError: [Errno 39] Directory not empty: '/blue/adamginsburg/abulatek/brick/symlinks/imaging_results/source_ab_146_spw51_reimaging_dirty_3sigma.mask' -> '/blue/adamginsburg/abulatek/brick/symlinks/imaging_results/source_ab_146_spw51_reimaging_dirty_3sigma_e2_d2.mask'
data_41
257
45
3
casa_clean_ab_257_spw45_2sigma_reimaging_FOV.log
--> CrashReporter initialized.

0%....10....20....30....40....50....60....70....80....90....100%

0%....10....20....30....40....50....60....70....80....90....100%
2022-07-27 19:39:40	WARN	SIImageStore::getPSFGaussian (file casa-source/code/synthesis/ImagerObjects/SIImageStore.cc, line 1916)	PSF is blank for[C3839:P0] 

0%....10....20....30....40....50....60....70....80....90....100%

0%....10....20....30....40....50....60....70....80....90....100%
2022-07-27 19:43:34	WARN	task_tclean::SIImageStore::restore (file casa-source/code/synthesis/ImagerObjects/SIImageStore.cc, line 2089)	Restoring with an empty model image. Only residuals will be processed to form the output restored image.
2022-07-27 19:45:48	SEVERE	tclean::task_tclean::casa	Exception from task_tclean : Restoration Error  : Error in copying internal T/F mask : Invalid Table operation: SetupNewTable /blue/adamginsburg/abulatek/brick/symlinks/imaging_results/source_ab_257_spw45_reimaging_dirty.image/mask0 is already opened (is in the table cache)
2022-07-27 19:45:50	SEVERE	tclean::::casa	Exception Reported: Error in tclean: Exception from task_tclean : Restoration Error  : Error in copying internal T/F mask : Invalid Table operation: SetupNewTable /blue/adamginsburg/abulatek/brick/symlinks/imaging_results/source_ab_257_spw45_reimaging_dirty.image/mask0 is already opened (is in the table cache)
optional configuration file config.py not found, continuing CASA startup without it
[22;0t]0;IPython: scripts/bashUsing matplotlib backend: agg
CASA 6.1.0.118 -- Common Astronomy Software Applications [6.1.0.118]
Data path is: /blue/adamginsburg/abulatek/brick/symlinks/data_41/calibrated_final.ms
Now creating dirty map: /blue/adamginsburg/abulatek/brick/symlinks/imaging_results/source_ab_257_spw45_reimaging_dirty
Dirty map creation successful!
Now measuring the mad_std in the dirty map
Standard deviation calculation successful! Result: 5.5 mJy/beam
Now masking the cube at 3 sigma
Masking successful!
Now computing boolmask
Boolmask computation successful!
Now getting coordinates from original image
Coordinates retrieved successfully!
Now outputting the mask file
Mask file output successful!
Now calculating the eroded/dilated boolmask
Eroded/dilated boolmask calculation successful!
Now defining the eroded/dilated mask to export
Now outputting the eroded/dilated mask
Eroded/dilated mask output successful!
Now renaming mask file for consistency
Telemetry initialized. Telemetry will send anonymized usage statistics to NRAO.
You can disable telemetry by adding the following line to the config.py file in your rcdir (e.g. ~/.casa/config.py):
telemetry_enabled = False
/blue/adamginsburg/adamginsburg/casa/casa-6.1.0-118/lib/py/lib/python3.6/site-packages/casa_formats_io/casa_dask.py:232: RuntimeWarning: divide by zero encountered in long_scalars
  factors = [f for f in range(stacks[dim] + 1) if stacks[dim] % f == 0]
WARNING: StokesWarning: Cube is a Stokes cube, returning spectral cube for I component [spectral_cube.io.core]
Traceback (most recent call last):
  File "/blue/adamginsburg/adamginsburg/casa/casa-6.1.0-118/lib/py/lib/python3.6/site-packages/casashell/private/init_system.py", line 159, in __evprop__
    run_path( args[0], init_globals=exec_globals, run_name='__main__' )
  File "/blue/adamginsburg/adamginsburg/casa/casa-6.1.0-118/lib/py/lib/python3.6/runpy.py", line 263, in run_path
    pkg_name=pkg_name, script_name=fname)
  File "/blue/adamginsburg/adamginsburg/casa/casa-6.1.0-118/lib/py/lib/python3.6/runpy.py", line 96, in _run_module_code
    mod_name, mod_spec, pkg_name, script_name)
  File "/blue/adamginsburg/adamginsburg/casa/casa-6.1.0-118/lib/py/lib/python3.6/runpy.py", line 85, in _run_code
    exec(code, run_globals)
  File "/blue/adamginsburg/abulatek/brick/scripts/imaging/reimaging_FOV.py", line 97, in <module>
    mask_image = make_mask(dirty_cube, dirty_map_image, sigma, 2, 2)
  File "/blue/adamginsburg/abulatek/brick/scripts/imaging/reimaging_FOV.py", line 80, in make_mask
    os.rename(mask_image+'.mask',mask_e_d_image+'.mask')
OSError: [Errno 39] Directory not empty: '/blue/adamginsburg/abulatek/brick/symlinks/imaging_results/source_ab_257_spw45_reimaging_dirty_3sigma.mask' -> '/blue/adamginsburg/abulatek/brick/symlinks/imaging_results/source_ab_257_spw45_reimaging_dirty_3sigma_e2_d2.mask'
